<robot xmlns:xacro="http://www.ros.org/wiki/xacro" name="sara">
	<!-- Import all Gazebo-customization elements, including Gazebo colors -->
	<xacro:include filename="$(find sara_description)/urdf/sara.gazebo"/>
	<!-- Import Rviz colors -->
	<!--<xacro:include filename="$(find sara_description)/urdf/materials.xacro"/>-->
	<!-- Used for fixing robot to Gazebo 'base_link' -->
	<link name="world"/>
	<joint name="fixed" type="fixed">
		<parent link="world"/>
		<child link="base"/>
	</joint>
	<!-- ++++++++++++++++++++++++++++++++++++++++ -->
	<!--                 LINKS                    -->
	<!-- ++++++++++++++++++++++++++++++++++++++++ -->
	<link name="base">
		<visual>
			<geometry>
				<mesh filename="package://sara_description/meshes/base/base.dae" scale="0.001 0.001 0.001"/>
			</geometry>
			<origin xyz="0 0 0"/>
		</visual>
		<collision>
			<geometry>
				<box size="0.5 0.5 0.025"/>
			</geometry>
			<origin xyz="0 0 0.0125"/>
		</collision>
		<inertial>
			<origin rpy="0 0 0" xyz="-0.03885 0.01799 0.02857"/>
			<mass value="5.355"/>
			<inertia ixx="0.07012" ixy="0.01315" ixz="0.003883" iyy="0.08717" iyz="-0.001922" izz="0.1535"/>
		</inertial>
	</link>
	<link name="link1">
		<visual>
			<geometry>
				<mesh filename="package://sara_description/meshes/link1/link1.dae" scale="0.001 0.001 0.001"/>
			</geometry>
			<origin xyz="0 0 0"/>
		</visual>
		<collision>
			<geometry>
				<box size="0.21 0.28 0.11"/>
			</geometry>
			<origin xyz="-0.06 0 0.14"/>
		</collision>
		<inertial>
			<origin rpy="0 0 0" xyz="-0.01183 -0.04885 0.17499"/>
			<mass value="8.178"/>
			<inertia ixx="0.03772" ixy="0.01084" ixz="0.01433" iyy="0.0473" iyz="-0.008177" izz="0.05586"/>
		</inertial>
	</link>
	<link name="link2">
		<visual>
			<geometry>
				<mesh filename="package://sara_description/meshes/link2/link2.dae" scale="0.001 0.001 0.001"/>
			</geometry>
			<origin xyz="0 0 0"/>
		</visual>
		<collision>
			<geometry>
				<box size="0.185 0.05 0.05"/>
			</geometry>
			<origin xyz="0.1325 0 0"/>
		</collision>
		<inertial>
			<origin rpy="0 0 0" xyz="0.1128 0 0.04572"/>
			<mass value="3.441"/>
			<inertia ixx="0.005329" ixy="-4.82256e-7" ixz="-0.0003582" iyy="0.01631" iyz="-0.000106414" izz="0.01304"/>
		</inertial>
	</link>
	<link name="link3">
		<visual>
			<geometry>
				<mesh filename="package://sara_description/meshes/link3/link3.dae" scale="0.001 0.001 0.001"/>
			</geometry>
			<origin xyz="0 0 0"/>
		</visual>
		<collision>
			<geometry>
				<box size="0.366 0.05 0.05"/>
			</geometry>
			<origin xyz="0.22 0 0.02" rpy="0 0.1047 0"/>
		</collision>
		<inertial>
			<origin rpy="0 0 0" xyz="0.17324 0 0.01793"/>
			<mass value="1.807"/>
			<inertia ixx="0.001707" ixy="3.38812e-7" ixz="0.001463" iyy="0.04448" iyz="-4.2067e-8" izz="0.04483"/>
		</inertial>
	</link>
	<link name="link4">
		<visual>
			<geometry>
				<mesh filename="package://sara_description/meshes/link4/link4.dae" scale="0.001 0.001 0.001"/>
			</geometry>
			<origin xyz="0 0 0"/>
		</visual>
		<collision>
			<geometry>
				<mesh filename="package://sara_description/meshes/link4/link4coll.stl" scale="0.001 0.001 0.001"/>
			</geometry>
			<origin xyz="0 0 0"/>
		</collision>
		<inertial>
			<origin rpy="0 0 0" xyz="0.04539 0.00733 0.00434"/>
			<mass value="1.045"/>
			<inertia ixx="0.001296" ixy="-0.0001774" ixz="-0.0002992" iyy="0.001766" iyz="-0.0001967" izz="0.002051"/>
		</inertial>
	</link>
	<link name="link5">
		<visual>
			<geometry>
				<mesh filename="package://sara_description/meshes/link5/link5small.dae" scale="0.001 0.001 0.001"/>
			</geometry>
			<origin xyz="0 0 0"/>
		</visual>
		<collision>
			<geometry>
				<mesh filename="package://sara_description/meshes/link5/link5collsmall.stl" scale="0.001 0.001 0.001"/>
			</geometry>
			<origin xyz="0 0 0"/>
		</collision>
		<inertial>
			<origin rpy="0 0 0" xyz="-0.017 0 0.003142"/>
			<mass value="0.8578"/>
			<inertia ixx="0.001494" ixy="-0.00000147219" ixz="-0.00002513" iyy="0.001114" iyz="-0.00000145665" izz="0.002344"/>
		</inertial>
	</link>
	<link name="link6">
		<visual>
			<geometry>
				<mesh filename="package://sara_description/meshes/link6/link6.dae" scale="0.001 0.001 0.001"/>
			</geometry>
			<origin xyz="0 0 0"/>
		</visual>
		<collision>
			<geometry>
				<mesh filename="package://sara_description/meshes/link6/link6coll.stl" scale="0.001 0.001 0.001"/>
			</geometry>
			<origin xyz="0 0 0"/>
		</collision>
		<inertial>
			<origin rpy="0 0 0" xyz="0.035 -0.017 0"/>
			<mass value="0.075"/>
			<inertia ixx="0.00001701" ixy="0.00000417082" ixz="-1.19483e-7" iyy="0.00008084" iyz="-1.19911e-7" izz="0.00008737"/>
		</inertial>
	</link>
	<link name="link7">
		<visual>
			<geometry>
				<mesh filename="package://sara_description/meshes/link7/link7.dae" scale="0.001 0.001 0.001"/>
			</geometry>
			<origin xyz="0 0 0"/>
		</visual>
		<collision>
			<geometry>
				<mesh filename="package://sara_description/meshes/link7/link7coll.stl" scale="0.001 0.001 0.001"/>
			</geometry>
			<origin xyz="0 0 0"/>
		</collision>
		<inertial>
			<origin rpy="0 0 0" xyz="0.035 0.017 0"/>
			<mass value="0.075"/>
			<inertia ixx="0.00001701" ixy="-0.00000417082" ixz="1.19483e-7" iyy="0.00008084" iyz="-1.19911e-7" izz="0.00008737"/>
		</inertial>
	</link>
	<!-- ++++++++++++++++++++++++++++++++++++++++ -->
	<!--         ADDITIONAL COLLISION             -->
	<!-- ++++++++++++++++++++++++++++++++++++++++ -->
	<link name="base_power_supply">
		<collision>
			<geometry>
				<box size=".125 .30 .05"/>
			</geometry>
			<origin xyz="-.175 .05 .045"/>
		</collision>
	</link>
	<joint name="base_add1" type="fixed">
		<parent link="base"/>
		<child link="base_power_supply"/>
	</joint>
	<!-- ++++++++++++++++++++++++++++++++++++++++ -->
	<!--                 JOINTS                   -->
	<!-- ++++++++++++++++++++++++++++++++++++++++ -->
	<joint name="joint1" type="continuous">
		<parent link="base"/>
		<child link="link1"/>
		<origin xyz="0 0 0"/>
		<axis xyz="0 0 1"/>
		<limit effort="1000.0" velocity="0.5"/>
	</joint>
	<joint name="joint2" type="revolute">
		<parent link="link1"/>
		<child link="link2"/>
		<origin xyz="0.0075 0 0.2311" rpy="0 -1.57 0"/>
		<axis xyz="0 1 0"/>
		<limit effort="1000.0" lower="-0.4" upper="1.8" velocity="0.5"/>
	</joint>
	<joint name="joint3" type="revolute">
		<parent link="link2"/>
		<child link="link3"/>
		<origin xyz="0.225 0 0" rpy="0 2.356 0"/>
		<axis xyz="0 1 0"/>
		<limit effort="1000.0" lower="-3.556" upper="0.594" velocity="0.5"/>
	</joint>
	<joint name="joint4" type="revolute">
		<parent link="link3"/>
		<child link="link4"/>
		<origin xyz=".386 0 0" rpy="0 -0.785 0"/>
		<axis xyz="0 1 0"/>
		<limit effort="1000.0" lower="-0.62" upper="2.3" velocity="0.5"/>
	</joint>
	<joint name="joint5" type="revolute">
		<parent link="link4"/>
		<child link="link5"/>
		<origin xyz="0.146 0 -0.003"/>
		<axis xyz="1 0 0"/>
		<limit effort="1000.0" lower="-3.14" upper="3.14" velocity="0.5"/>
	</joint>
	<joint name="joint6" type="revolute">
		<parent link="link5"/>
		<child link="link6"/>
		<origin xyz="0.035 -0.018 0"/>
		<axis xyz="0 0 -1"/>
		<limit effort="1000.0" lower="-0.25" upper="0.40" velocity="0.5"/>
	</joint>
	<joint name="joint7" type="revolute">
		<parent link="link5"/>
		<child link="link7"/>
		<origin xyz="0.035 0.018 0"/>
		<axis xyz="0 0 1"/>
		<mimic joint="joint6" multiplier="1"/>
		<limit effort="1000.0" lower="-0.40" upper="0.25" velocity="0.5"/>
	</joint>
	<!-- ++++++++++++++++++++++++++++++++++++++++ -->
	<!--              TRANSMISSIONS               -->
	<!-- ++++++++++++++++++++++++++++++++++++++++ -->
	<transmission name="tran1">
		<type>transmission_interface/SimpleTransmission</type>
		<joint name="joint1">
			<hardwareInterface>hardware_interface/PositionJointInterface</hardwareInterface>
		</joint>
		<actuator name="motor1">
			<hardwareInterface>hardware_interface/PositionJointInterface</hardwareInterface>
			<mechanicalReduction>1</mechanicalReduction>
		</actuator>
	</transmission>
	<transmission name="tran2">
		<type>transmission_interface/SimpleTransmission</type>
		<joint name="joint2">
			<hardwareInterface>hardware_interface/PositionJointInterface</hardwareInterface>
		</joint>
		<actuator name="motor2">
			<hardwareInterface>hardware_interface/PositionJointInterface</hardwareInterface>
			<mechanicalReduction>1</mechanicalReduction>
		</actuator>
	</transmission>
	<transmission name="tran3">
		<type>transmission_interface/SimpleTransmission</type>
		<joint name="joint3">
			<hardwareInterface>hardware_interface/PositionJointInterface</hardwareInterface>
		</joint>
		<actuator name="motor3">
			<hardwareInterface>hardware_interface/PositionJointInterface</hardwareInterface>
			<mechanicalReduction>1</mechanicalReduction>
		</actuator>
	</transmission>
	<transmission name="tran4">
		<type>transmission_interface/SimpleTransmission</type>
		<joint name="joint4">
			<hardwareInterface>hardware_interface/PositionJointInterface</hardwareInterface>
		</joint>
		<actuator name="motor4">
			<hardwareInterface>hardware_interface/PositionJointInterface</hardwareInterface>
			<mechanicalReduction>1</mechanicalReduction>
		</actuator>
	</transmission>
	<transmission name="tran5">
		<type>transmission_interface/SimpleTransmission</type>
		<joint name="joint5">
			<hardwareInterface>hardware_interface/PositionJointInterface</hardwareInterface>
		</joint>
		<actuator name="motor5">
			<hardwareInterface>hardware_interface/PositionJointInterface</hardwareInterface>
			<mechanicalReduction>1</mechanicalReduction>
		</actuator>
	</transmission>
	<transmission name="tran6">
		<type>transmission_interface/SimpleTransmission</type>
		<joint name="joint6">
			<hardwareInterface>hardware_interface/PositionJointInterface</hardwareInterface>
		</joint>
		<actuator name="motor6">
			<hardwareInterface>hardware_interface/PositionJointInterface</hardwareInterface>
			<mechanicalReduction>1</mechanicalReduction>
		</actuator>
	</transmission>
	<transmission name="tran7">
		<type>transmission_interface/SimpleTransmission</type>
		<joint name="joint7">
			<hardwareInterface>hardware_interface/PositionJointInterface</hardwareInterface>
		</joint>
		<actuator name="motor7">
			<hardwareInterface>hardware_interface/PositionJointInterface</hardwareInterface>
			<mechanicalReduction>1</mechanicalReduction>
		</actuator>
	</transmission>
</robot>
